Workbook

Sheet System Parameters (Sensor)
A3: System Parameters (defined by hardware) | E3: Profiles (usage of each component mode - defined by software and usage)
B4: form the datasheets
E5: "Time keeping" | F5: "alarmimg" | G5: "Setting"
A6: Processor
A7: Active | B7: 89.1 | C7: mW | E7: 0.05 | F7: 0 | G7: 0.2
A8: Idle | B8: 33 | C8: mW | E8: 0.9 | F8: 1 | G8: 0.7
A9: Sleep | B9: 0.145 | C9: mW | E9: 0.05 | F9: 0 | G9: 0.1
A11: LED
A12: On | B12: 16.5 | C12: mW | E12: 0 | F12: 1 | G12: 0.5
A15: Needle Gauge
A16: On | B16: 750 | C16: mW | E16: 0 | F16: 0 | G16: 0.05
A17: Idle | B17: 50 | C17: mW | E17: 1 | F17: 1 | G17: 0.95
A18: Off | B18: 0 | C18: mW | E18: 0 | F18: 0 | G18: 0
A20: Display
A21: On | B21: 16.5 | C21: mW | E21: 1 | F21: 0 | G21: 0
A22: Off (leakage) | B22: 0 | C22: mW | E22: 0 | F22: 1 | G22: 1
A24: Piezo Buzzer
A25: Data Rate | B25: 0 | C25: bps | E25: 0 | F25: 0 | G25: 0 | L25: Total power in profile (mw) | O25: Maximum Time
A26: On | B26: 33 | C26: mW | E26: 0 | F26: 1 | G26: 0 | L26: =E5 -> "Time keeping" | M26: =SUMPRODUCT(B7:B28, E7:E28) -> 100.66225 | N26: mW | O26: =$M$31/M26 -> 17.459375 | P26: hours
A27: - | B27: 0 | C27: mW | E27: 0 | F27: 0 | G27: 0 | L27: =F5 -> "alarmimg" | M27: =SUMPRODUCT(B7:B28, F7:F28) -> 132.5 | N27: mW | O27: =$M$31/M27 -> 13.264151 | P27: hours
A28: - | B28: 0 | C28: mW | E28: 0 | F28: 0 | G28: 0 | L28: =G5 -> "Setting" | M28: =SUMPRODUCT(B7:B28, G7:G28) -> 134.1845 | N28: mW | O28: =$M$31/M28 -> 13.097638 | P28: hours
E30: 23 | F30: 1 | G30: 0 | H30: hours/day typical usage | L30: Effective Battery Capacity
A31: Battery | M31: =B32*B33*B34 -> 1757.5 | N31: mW*h
A32: Capacity | B32: 500 | C32: mAh
A33: Nominal Voltage | B33: 3.7 | C33: V | L33: Days of Use | M33: =M31/(E30*M26+F30*M27+G30*M28) -> 0.71801169 | N33: days
A34: Regulator Efficiency | B34: 0.95 | L34: Hours of Use | M34: =M33*24 -> 17.23228 | N34: hours
A38: REFLECTIONS : WHAT DID YOU LEARN FROM ANALYZING YOUR POWER. TALK ABOUT SOME POTENTIAL TRADEOFFS.

Sheet Sensitivity Analysis (Sensor)
A50: Linked Data from First Page DO NOT EDIT
A52: ='System Parameters (Sensor)'!A3 -> System Parameters (defined by hardware) | B52: ='System Parameters (Sensor)'!B3 -> 0 | C52: ='System Parameters (Sensor)'!C3 -> 0 | D52: ='System Parameters (Sensor)'!D3 -> 0 | T52: ='System Parameters (Sensor)'!E3 -> Profiles (usage of each component mode - defined by software and usage) | U52: ='System Parameters (Sensor)'!F3 -> 0 | V52: ='System Parameters (Sensor)'!G3 -> 0 | W52: ='System Parameters (Sensor)'!H3 -> 0
A53: ='System Parameters (Sensor)'!A4 -> 0 | B53: ='System Parameters (Sensor)'!B4 -> form the datasheets | C53: ='System Parameters (Sensor)'!C4 -> 0 | D53: ='System Parameters (Sensor)'!D4 -> 0 | T53: ='System Parameters (Sensor)'!E4 -> 0 | U53: ='System Parameters (Sensor)'!F4 -> 0 | V53: ='System Parameters (Sensor)'!G4 -> 0 | W53: ='System Parameters (Sensor)'!H4 -> 0
A54: ='System Parameters (Sensor)'!A5 -> 0 | B54: ='System Parameters (Sensor)'!B5 -> 0 | C54: ='System Parameters (Sensor)'!C5 -> 0 | D54: ='System Parameters (Sensor)'!D5 -> 0 | T54: ='System Parameters (Sensor)'!E5 -> "Time keeping" | U54: ='System Parameters (Sensor)'!F5 -> "alarmimg" | V54: ='System Parameters (Sensor)'!G5 -> "Setting" | W54: ='System Parameters (Sensor)'!H5 -> 0
A55: ='System Parameters (Sensor)'!A6 -> Processor | B55: ='System Parameters (Sensor)'!B6 -> 0 | C55: ='System Parameters (Sensor)'!C6 -> 0 | D55: ='System Parameters (Sensor)'!D6 -> 0 | T55: ='System Parameters (Sensor)'!E6 -> 0 | U55: ='System Parameters (Sensor)'!F6 -> 0 | V55: ='System Parameters (Sensor)'!G6 -> 0 | W55: ='System Parameters (Sensor)'!H6 -> 0
A56: ='System Parameters (Sensor)'!A7 -> Active | B56: ='System Parameters (Sensor)'!B7 -> 89.1 | C56: ='System Parameters (Sensor)'!C7 -> mW | D56: =$B56*0.9 -> 80.19 | E56: =$B56 -> 89.1 | F56: =$B56 -> 89.1 | G56: =$B56 -> 89.1 | H56: =$B56 -> 89.1 | I56: =$B56 -> 89.1 | J56: =$B56 -> 89.1 | K56: =$B56 -> 89.1 | L56: =$B56 -> 89.1 | ... O56: =$B56 -> 89.1 | T56: ='System Parameters (Sensor)'!E7 -> 0.05 | U56: ='System Parameters (Sensor)'!F7 -> 0 | V56: ='System Parameters (Sensor)'!G7 -> 0.2 | W56: ='System Parameters (Sensor)'!H7 -> 0
A57: ='System Parameters (Sensor)'!A8 -> Idle | B57: ='System Parameters (Sensor)'!B8 -> 33 | C57: ='System Parameters (Sensor)'!C8 -> mW | D57: =$B57 -> 33 | E57: =$B57*0.9 -> 29.7 | F57: =$B57 -> 33 | G57: =$B57 -> 33 | H57: =$B57 -> 33 | I57: =$B57 -> 33 | J57: =$B57 -> 33 | K57: =$B57 -> 33 | L57: =$B57 -> 33 | M57: =$B57 -> 33 | ... O57: =$B57 -> 33 | T57: ='System Parameters (Sensor)'!E8 -> 0.9 | U57: ='System Parameters (Sensor)'!F8 -> 1 | V57: ='System Parameters (Sensor)'!G8 -> 0.7 | W57: ='System Parameters (Sensor)'!H8 -> 0
A58: ='System Parameters (Sensor)'!A9 -> Sleep | B58: ='System Parameters (Sensor)'!B9 -> 0.145 | C58: ='System Parameters (Sensor)'!C9 -> mW | D58: =$B58 -> 0.145 | E58: =$B58 -> 0.145 | F58: =$B58*0.9 -> 0.1305 | G58: =$B58 -> 0.145 | H58: =$B58 -> 0.145 | I58: =$B58 -> 0.145 | J58: =$B58 -> 0.145 | K58: =$B58 -> 0.145 | L58: =$B58 -> 0.145 | M58: =$B58 -> 0.145 | N58: =$B58 -> 0.145 | O58: =$B58 -> 0.145 | T58: ='System Parameters (Sensor)'!E9 -> 0.05 | U58: ='System Parameters (Sensor)'!F9 -> 0 | V58: ='System Parameters (Sensor)'!G9 -> 0.1 | W58: ='System Parameters (Sensor)'!H9 -> 0
A59: ='System Parameters (Sensor)'!A10 -> 0 | B59: ='System Parameters (Sensor)'!B10 -> 0 | C59: ='System Parameters (Sensor)'!C10 -> 0 | D59: =$B59 -> 0 | E59: =$B59 -> 0 | F59: =$B59 -> 0 | G59: =$B59 -> 0 | H59: =$B59 -> 0 | I59: =$B59 -> 0 | J59: =$B59 -> 0 | K59: =$B59 -> 0 | ... O59: =$B59 -> 0 | T59: ='System Parameters (Sensor)'!E10 -> 0 | U59: ='System Parameters (Sensor)'!F10 -> 0 | V59: ='System Parameters (Sensor)'!G10 -> 0 | W59: ='System Parameters (Sensor)'!H10 -> 0
A60: ='System Parameters (Sensor)'!A11 -> LED | B60: ='System Parameters (Sensor)'!B11 -> 0 | C60: ='System Parameters (Sensor)'!C11 -> 0 | D60: =$B60 -> 0 | E60: =$B60 -> 0 | F60: =$B60 -> 0 | G60: =$B60 -> 0 | H60: =$B60 -> 0 | I60: =$B60 -> 0 | J60: =$B60 -> 0 | K60: =$B60 -> 0 | ... O60: =$B60 -> 0 | T60: ='System Parameters (Sensor)'!E11 -> 0 | U60: ='System Parameters (Sensor)'!F11 -> 0 | V60: ='System Parameters (Sensor)'!G11 -> 0 | W60: ='System Parameters (Sensor)'!H11 -> 0
A61: ='System Parameters (Sensor)'!A12 -> On | B61: ='System Parameters (Sensor)'!B12 -> 16.5 | C61: ='System Parameters (Sensor)'!C12 -> mW | D61: =$B61 -> 16.5 | E61: =$B61 -> 16.5 | F61: =$B61 -> 16.5 | G61: =$B61*0.9 -> 14.85 | H61: =$B61 -> 16.5 | I61: =$B61 -> 16.5 | J61: =$B61 -> 16.5 | K61: =$B61 -> 16.5 | L61: =$B61 -> 16.5 | M61: =$B61 -> 16.5 | N61: =$B61 -> 16.5 | O61: =$B61 -> 16.5 | T61: ='System Parameters (Sensor)'!E12 -> 0 | U61: ='System Parameters (Sensor)'!F12 -> 1 | V61: ='System Parameters (Sensor)'!G12 -> 0.5 | W61: ='System Parameters (Sensor)'!H12 -> 0
A62: ='System Parameters (Sensor)'!A13 -> 0 | B62: ='System Parameters (Sensor)'!B13 -> 0 | C62: ='System Parameters (Sensor)'!C13 -> 0 | D62: =$B62 -> 0 | E62: =$B62 -> 0 | F62: =$B62 -> 0 | G62: =$B62 -> 0 | H62: =$B62 -> 0 | I62: =$B62 -> 0 | J62: =$B62 -> 0 | K62: =$B62 -> 0 | ... O62: =$B62 -> 0 | T62: ='System Parameters (Sensor)'!E13 -> 0 | U62: ='System Parameters (Sensor)'!F13 -> 0 | V62: ='System Parameters (Sensor)'!G13 -> 0 | W62: ='System Parameters (Sensor)'!H13 -> 0
A63: ='System Parameters (Sensor)'!A14 -> 0 | B63: ='System Parameters (Sensor)'!B14 -> 0 | C63: ='System Parameters (Sensor)'!C14 -> 0 | D63: =$B63 -> 0 | E63: =$B63 -> 0 | F63: =$B63 -> 0 | G63: =$B63 -> 0 | H63: =$B63 -> 0 | I63: =$B63 -> 0 | J63: =$B63 -> 0 | K63: =$B63 -> 0 | ... O63: =$B63 -> 0 | T63: ='System Parameters (Sensor)'!E14 -> 0 | U63: ='System Parameters (Sensor)'!F14 -> 0 | V63: ='System Parameters (Sensor)'!G14 -> 0 | W63: ='System Parameters (Sensor)'!H14 -> 0
A64: ='System Parameters (Sensor)'!A15 -> Needle Gauge | B64: ='System Parameters (Sensor)'!B15 -> 0 | C64: ='System Parameters (Sensor)'!C15 -> 0 | D64: =$B64 -> 0 | E64: =$B64 -> 0 | F64: =$B64 -> 0 | G64: =$B64 -> 0 | H64: =$B64 -> 0 | I64: =$B64 -> 0 | J64: =$B64 -> 0 | K64: =$B64 -> 0 | ... O64: =$B64 -> 0 | T64: ='System Parameters (Sensor)'!E15 -> 0 | U64: ='System Parameters (Sensor)'!F15 -> 0 | V64: ='System Parameters (Sensor)'!G15 -> 0 | W64: ='System Parameters (Sensor)'!H15 -> 0
A65: ='System Parameters (Sensor)'!A16 -> On | B65: ='System Parameters (Sensor)'!B16 -> 750 | C65: ='System Parameters (Sensor)'!C16 -> mW | D65: =$B65 -> 750 | E65: =$B65 -> 750 | F65: =$B65 -> 750 | G65: =$B65 -> 750 | H65: =$B65*0.9 -> 675 | I65: =$B65 -> 750 | J65: =$B65 -> 750 | K65: =$B65 -> 750 | L65: =$B65 -> 750 | M65: =$B65 -> 750 | N65: =$B65 -> 750 | O65: =$B65 -> 750 | T65: ='System Parameters (Sensor)'!E16 -> 0 | U65: ='System Parameters (Sensor)'!F16 -> 0 | V65: ='System Parameters (Sensor)'!G16 -> 0.05 | W65: ='System Parameters (Sensor)'!H16 -> 0
A66: ='System Parameters (Sensor)'!A17 -> Idle | B66: ='System Parameters (Sensor)'!B17 -> 50 | C66: ='System Parameters (Sensor)'!C17 -> mW | D66: =$B66 -> 50 | E66: =$B66 -> 50 | F66: =$B66 -> 50 | G66: =$B66 -> 50 | H66: =$B66 -> 50 | I66: =$B66*0.9 -> 45 | J66: =$B66 -> 50 | K66: =$B66 -> 50 | L66: =$B66 -> 50 | M66: =$B66 -> 50 | N66: =$B66 -> 50 | O66: =$B66 -> 50 | T66: ='System Parameters (Sensor)'!E17 -> 1 | U66: ='System Parameters (Sensor)'!F17 -> 1 | V66: ='System Parameters (Sensor)'!G17 -> 0.95 | W66: ='System Parameters (Sensor)'!H17 -> 0
A67: ='System Parameters (Sensor)'!A18 -> Off | B67: ='System Parameters (Sensor)'!B18 -> 0 | C67: ='System Parameters (Sensor)'!C18 -> mW | D67: =$B67 -> 0 | E67: =$B67 -> 0 | F67: =$B67 -> 0 | G67: =$B67 -> 0 | H67: =$B67 -> 0 | I67: =$B67 -> 0 | J67: =$B67*0.9 -> 0 | K67: =$B67 -> 0 | L67: =$B67 -> 0 | M67: =$B67 -> 0 | N67: =$B67 -> 0 | O67: =$B67 -> 0 | T67: ='System Parameters (Sensor)'!E18 -> 0 | U67: ='System Parameters (Sensor)'!F18 -> 0 | V67: ='System Parameters (Sensor)'!G18 -> 0 | W67: ='System Parameters (Sensor)'!H18 -> 0
A68: ='System Parameters (Sensor)'!A19 -> 0 | B68: ='System Parameters (Sensor)'!B19 -> 0 | C68: ='System Parameters (Sensor)'!C19 -> 0 | D68: =$B68 -> 0 | E68: =$B68 -> 0 | F68: =$B68 -> 0 | G68: =$B68 -> 0 | H68: =$B68 -> 0 | I68: =$B68 -> 0 | J68: =$B68 -> 0 | K68: =$B68 -> 0 | ... O68: =$B68 -> 0 | T68: ='System Parameters (Sensor)'!E19 -> 0 | U68: ='System Parameters (Sensor)'!F19 -> 0 | V68: ='System Parameters (Sensor)'!G19 -> 0 | W68: ='System Parameters (Sensor)'!H19 -> 0
A69: ='System Parameters (Sensor)'!A20 -> Display | B69: ='System Parameters (Sensor)'!B20 -> 0 | C69: ='System Parameters (Sensor)'!C20 -> 0 | D69: =$B69 -> 0 | E69: =$B69 -> 0 | F69: =$B69 -> 0 | G69: =$B69 -> 0 | H69: =$B69 -> 0 | I69: =$B69 -> 0 | J69: =$B69 -> 0 | K69: =$B69 -> 0 | ... O69: =$B69 -> 0 | T69: ='System Parameters (Sensor)'!E20 -> 0 | U69: ='System Parameters (Sensor)'!F20 -> 0 | V69: ='System Parameters (Sensor)'!G20 -> 0 | W69: ='System Parameters (Sensor)'!H20 -> 0
A70: ='System Parameters (Sensor)'!A21 -> On | B70: ='System Parameters (Sensor)'!B21 -> 16.5 | C70: ='System Parameters (Sensor)'!C21 -> mW | D70: =$B70 -> 16.5 | E70: =$B70 -> 16.5 | F70: =$B70 -> 16.5 | G70: =$B70 -> 16.5 | H70: =$B70 -> 16.5 | I70: =$B70 -> 16.5 | J70: =$B70 -> 16.5 | K70: =$B70*0.9 -> 14.85 | L70: =$B70 -> 16.5 | M70: =$B70 -> 16.5 | N70: =$B70 -> 16.5 | O70: =$B70 -> 16.5 | T70: ='System Parameters (Sensor)'!E21 -> 1 | U70: ='System Parameters (Sensor)'!F21 -> 0 | V70: ='System Parameters (Sensor)'!G21 -> 0 | W70: ='System Parameters (Sensor)'!H21 -> 0
A71: ='System Parameters (Sensor)'!A22 -> Off (leakage) | B71: ='System Parameters (Sensor)'!B22 -> 0 | C71: ='System Parameters (Sensor)'!C22 -> mW | D71: =$B71 -> 0 | E71: =$B71 -> 0 | F71: =$B71 -> 0 | G71: =$B71 -> 0 | H71: =$B71 -> 0 | I71: =$B71 -> 0 | J71: =$B71 -> 0 | K71: =$B71 -> 0 | L71: =$B71*0.9 -> 0 | M71: =$B71 -> 0 | N71: =$B71 -> 0 | O71: =$B71 -> 0 | T71: ='System Parameters (Sensor)'!E22 -> 0 | U71: ='System Parameters (Sensor)'!F22 -> 1 | V71: ='System Parameters (Sensor)'!G22 -> 1 | W71: ='System Parameters (Sensor)'!H22 -> 0
A72: ='System Parameters (Sensor)'!A23 -> 0 | B72: ='System Parameters (Sensor)'!B23 -> 0 | C72: ='System Parameters (Sensor)'!C23 -> 0 | D72: =$B72 -> 0 | E72: =$B72 -> 0 | F72: =$B72 -> 0 | G72: =$B72 -> 0 | H72: =$B72 -> 0 | I72: =$B72 -> 0 | J72: =$B72 -> 0 | K72: =$B72 -> 0 | ... O72: =$B72 -> 0 | T72: ='System Parameters (Sensor)'!E23 -> 0 | U72: ='System Parameters (Sensor)'!F23 -> 0 | V72: ='System Parameters (Sensor)'!G23 -> 0 | W72: ='System Parameters (Sensor)'!H23 -> 0
A73: ='System Parameters (Sensor)'!A24 -> Piezo Buzzer | B73: ='System Parameters (Sensor)'!B24 -> 0 | C73: ='System Parameters (Sensor)'!C24 -> 0 | D73: =$B73 -> 0 | E73: =$B73 -> 0 | F73: =$B73 -> 0 | G73: =$B73 -> 0 | H73: =$B73 -> 0 | I73: =$B73 -> 0 | J73: =$B73 -> 0 | K73: =$B73 -> 0 | ... O73: =$B73 -> 0 | T73: ='System Parameters (Sensor)'!E24 -> 0 | U73: ='System Parameters (Sensor)'!F24 -> 0 | V73: ='System Parameters (Sensor)'!G24 -> 0 | W73: ='System Parameters (Sensor)'!H24 -> 0
A74: ='System Parameters (Sensor)'!A26 -> On | B74: ='System Parameters (Sensor)'!B26 -> 33 | C74: ='System Parameters (Sensor)'!C26 -> mW | D74: =$B74 -> 33 | E74: =$B74 -> 33 | F74: =$B74 -> 33 | G74: =$B74 -> 33 | H74: =$B74 -> 33 | I74: =$B74 -> 33 | J74: =$B74 -> 33 | K74: =$B74 -> 33 | L74: =$B74 -> 33 | M74: =$B74*0.9 -> 29.7 | N74: =$B74 -> 33 | O74: =$B74 -> 33 | T74: ='System Parameters (Sensor)'!E26 -> 0 | U74: ='System Parameters (Sensor)'!F26 -> 1 | V74: ='System Parameters (Sensor)'!G26 -> 0 | W74: ='System Parameters (Sensor)'!H26 -> 0
A75: ='System Parameters (Sensor)'!A27 -> - | B75: ='System Parameters (Sensor)'!B27 -> 0 | C75: ='System Parameters (Sensor)'!C27 -> mW | D75: =$B75 -> 0 | E75: =$B75 -> 0 | F75: =$B75 -> 0 | G75: =$B75 -> 0 | H75: =$B75 -> 0 | I75: =$B75 -> 0 | J75: =$B75 -> 0 | K75: =$B75 -> 0 | ... M75: =$B75 -> 0 | N75: =$B75*0.9 -> 0 | O75: =$B75 -> 0 | T75: ='System Parameters (Sensor)'!E27 -> 0 | U75: ='System Parameters (Sensor)'!F27 -> 0 | V75: ='System Parameters (Sensor)'!G27 -> 0 | W75: ='System Parameters (Sensor)'!H27 -> 0
A76: ='System Parameters (Sensor)'!A28 -> - | B76: ='System Parameters (Sensor)'!B28 -> 0 | C76: ='System Parameters (Sensor)'!C28 -> mW | D76: =$B76 -> 0 | E76: =$B76 -> 0 | F76: =$B76 -> 0 | G76: =$B76 -> 0 | H76: =$B76 -> 0 | I76: =$B76 -> 0 | J76: =$B76 -> 0 | K76: =$B76 -> 0 | ... N76: =$B76 -> 0 | O76: =$B76*0.9 -> 0 | T76: ='System Parameters (Sensor)'!E28 -> 0 | U76: ='System Parameters (Sensor)'!F28 -> 0 | V76: ='System Parameters (Sensor)'!G28 -> 0 | W76: ='System Parameters (Sensor)'!H28 -> 0
A77: ='System Parameters (Sensor)'!A29 -> 0 | B77: ='System Parameters (Sensor)'!B29 -> 0 | C77: ='System Parameters (Sensor)'!C29 -> 0 | D77: ='System Parameters (Sensor)'!D29 -> 0 | T77: ='System Parameters (Sensor)'!E29 -> 0 | U77: ='System Parameters (Sensor)'!F29 -> 0 | V77: ='System Parameters (Sensor)'!G29 -> 0 | W77: ='System Parameters (Sensor)'!H29 -> 0
A78: ='System Parameters (Sensor)'!A30 -> 0 | B78: ='System Parameters (Sensor)'!B30 -> 0 | C78: ='System Parameters (Sensor)'!C30 -> 0 | D78: ='System Parameters (Sensor)'!D30 -> 0 | T78: ='System Parameters (Sensor)'!E30 -> 23 | U78: ='System Parameters (Sensor)'!F30 -> 1 | V78: ='System Parameters (Sensor)'!G30 -> 0 | W78: ='System Parameters (Sensor)'!H30 -> hours/day typical usage
A79: ='System Parameters (Sensor)'!A31 -> Battery | B79: ='System Parameters (Sensor)'!B31 -> 0 | C79: ='System Parameters (Sensor)'!C31 -> 0 | D79: ='System Parameters (Sensor)'!D31 -> 0 | T79: ='System Parameters (Sensor)'!E31 -> 0 | U79: ='System Parameters (Sensor)'!F31 -> 0 | V79: ='System Parameters (Sensor)'!G31 -> 0 | W79: ='System Parameters (Sensor)'!H31 -> 0
A80: ='System Parameters (Sensor)'!A32 -> Capacity | B80: ='System Parameters (Sensor)'!B32 -> 500 | C80: ='System Parameters (Sensor)'!C32 -> mAh | D80: ='System Parameters (Sensor)'!D32 -> 0 | T80: ='System Parameters (Sensor)'!E32 -> 0 | U80: ='System Parameters (Sensor)'!F32 -> 0 | V80: ='System Parameters (Sensor)'!G32 -> 0 | W80: ='System Parameters (Sensor)'!H32 -> 0
A81: ='System Parameters (Sensor)'!A33 -> Nominal Voltage | B81: ='System Parameters (Sensor)'!B33 -> 3.7 | C81: ='System Parameters (Sensor)'!C33 -> V | D81: ='System Parameters (Sensor)'!D33 -> 0 | T81: ='System Parameters (Sensor)'!E33 -> 0 | U81: ='System Parameters (Sensor)'!F33 -> 0 | V81: ='System Parameters (Sensor)'!G33 -> 0 | W81: ='System Parameters (Sensor)'!H33 -> 0
A82: ='System Parameters (Sensor)'!A34 -> Regulator Efficiency | B82: ='System Parameters (Sensor)'!B34 -> 0.95 | C82: ='System Parameters (Sensor)'!C34 -> 0 | D82: ='System Parameters (Sensor)'!D34 -> 0 | T82: ='System Parameters (Sensor)'!E34 -> 0 | U82: ='System Parameters (Sensor)'!F34 -> 0 | V82: ='System Parameters (Sensor)'!G34 -> 0 | W82: ='System Parameters (Sensor)'!H34 -> 0
A83: ='System Parameters (Sensor)'!A35 -> 0 | B83: ='System Parameters (Sensor)'!B35 -> 0 | C83: ='System Parameters (Sensor)'!C35 -> 0 | D83: ='System Parameters (Sensor)'!D35 -> 0 | O83: ='System Parameters (Sensor)'!E35 -> 0 | P83: ='System Parameters (Sensor)'!F35 -> 0 | Q83: ='System Parameters (Sensor)'!G35 -> 0 | R83: ='System Parameters (Sensor)'!H35 -> 0 | S83: ='System Parameters (Sensor)'!I35 -> 0 | T83: ='System Parameters (Sensor)'!J35 -> 0 | U83: =#REF! -> #REF! | V83: =#REF! -> #REF!
A84: ='System Parameters (Sensor)'!A36 -> 0 | B84: ='System Parameters (Sensor)'!B36 -> 0 | C84: ='System Parameters (Sensor)'!C36 -> 0 | D84: ='System Parameters (Sensor)'!D36 -> 0 | O84: ='System Parameters (Sensor)'!E36 -> 0 | P84: ='System Parameters (Sensor)'!F36 -> 0 | Q84: ='System Parameters (Sensor)'!G36 -> 0 | R84: ='System Parameters (Sensor)'!H36 -> 0 | S84: ='System Parameters (Sensor)'!I36 -> 0 | T84: ='System Parameters (Sensor)'!J36 -> 0 | U84: =#REF! -> #REF! | V84: =#REF! -> #REF!
A85: ='System Parameters (Sensor)'!A37 -> 0 | B85: ='System Parameters (Sensor)'!K24 -> 0 | C85: ='System Parameters (Sensor)'!L24 -> 0 | D85: ='System Parameters (Sensor)'!M24 -> 0 | O85: ='System Parameters (Sensor)'!N24 -> 0 | P85: ='System Parameters (Sensor)'!O24 -> 0 | Q85: ='System Parameters (Sensor)'!P24 -> 0 | R85: ='System Parameters (Sensor)'!Q24 -> 0 | S85: ='System Parameters (Sensor)'!I37 -> 0 | T85: ='System Parameters (Sensor)'!J37 -> 0 | U85: =#REF! -> #REF! | V85: =#REF! -> #REF!
A86: ='System Parameters (Sensor)'!A38 -> REFLECTIONS : WHAT DID YOU LEARN FROM ANALYZING YOUR POWER. TALK ABOUT SOME POTENTIAL TRADEOFFS. | B86: ='System Parameters (Sensor)'!K25 -> 0 | C86: =#REF! -> #REF! | D86: =#REF! -> #REF! | O86: =#REF! -> #REF! | P86: =#REF! -> #REF! | Q86: =#REF! -> #REF! | R86: ='System Parameters (Sensor)'!Q25 -> 0 | S86: ='System Parameters (Sensor)'!I38 -> 0 | T86: ='System Parameters (Sensor)'!J38 -> 0 | U86: =#REF! -> #REF! | V86: =#REF! -> #REF!
A87: ='System Parameters (Sensor)'!L25 -> Total power in profile (mw) | B87: ='System Parameters (Sensor)'!M25 -> 0 | C87: ='System Parameters (Sensor)'!N25 -> 0 | R87: ='System Parameters (Sensor)'!Q26 -> 0 | S87: ='System Parameters (Sensor)'!I39 -> 0 | T87: ='System Parameters (Sensor)'!J39 -> 0 | U87: ='System Parameters (Sensor)'!K39 -> 0 | V87: ='System Parameters (Sensor)'!L39 -> 0
A88: ='System Parameters (Sensor)'!L26 -> "Time keeping" | B88: =SUMPRODUCT(B56:B76, $T56:$T76) -> 100.66225 | C88: ='System Parameters (Sensor)'!N26 -> mW | D88: =SUMPRODUCT(D56:D76, $T56:$T76) -> 100.21675 | E88: =SUMPRODUCT(E56:E76, $T56:$T76) -> 97.69225 | F88: =SUMPRODUCT(F56:F76, $T56:$T76) -> 100.66153 | G88: =SUMPRODUCT(G56:G76, $T56:$T76) -> 100.66225 | H88: =SUMPRODUCT(H56:H76, $T56:$T76) -> 100.66225 | I88: =SUMPRODUCT(I56:I76, $T56:$T76) -> 95.66225 | J88: =SUMPRODUCT(J56:J76, $T56:$T76) -> 100.66225 | K88: =SUMPRODUCT(K56:K76, $T56:$T76) -> 99.01225 | ... O88: =SUMPRODUCT(O56:O76, $T56:$T76) -> 100.66225 | R88: ='System Parameters (Sensor)'!Q27 -> 0 | S88: ='System Parameters (Sensor)'!I40 -> 0 | T88: ='System Parameters (Sensor)'!J40 -> 0 | U88: ='System Parameters (Sensor)'!K40 -> 0 | V88: ='System Parameters (Sensor)'!L40 -> 0
A89: ='System Parameters (Sensor)'!L27 -> "alarmimg" | B89: =SUMPRODUCT(B56:B76,$U56:$U76) -> 132.5 | C89: ='System Parameters (Sensor)'!N27 -> mW | D89: =SUMPRODUCT(D56:D76,$U56:$U76) -> 132.5 | E89: =SUMPRODUCT(E56:E76,$U56:$U76) -> 129.2 | F89: =SUMPRODUCT(F56:F76,$U56:$U76) -> 132.5 | G89: =SUMPRODUCT(G56:G76,$U56:$U76) -> 130.85 | H89: =SUMPRODUCT(H56:H76,$U56:$U76) -> 132.5 | I89: =SUMPRODUCT(I56:I76,$U56:$U76) -> 127.5 | J89: =SUMPRODUCT(J56:J76,$U56:$U76) -> 132.5 | K89: =SUMPRODUCT(K56:K76,$U56:$U76) -> 132.5 | ... O89: =SUMPRODUCT(O56:O76,$U56:$U76) -> 132.5 | R89: ='System Parameters (Sensor)'!Q28 -> 0 | S89: ='System Parameters (Sensor)'!I41 -> 0 | T89: ='System Parameters (Sensor)'!J41 -> 0 | U89: ='System Parameters (Sensor)'!K41 -> 0 | V89: ='System Parameters (Sensor)'!L41 -> 0
A90: ='System Parameters (Sensor)'!L28 -> "Setting" | B90: =SUMPRODUCT(B56:B76, $V56:$V76) -> 134.1845 | C90: ='System Parameters (Sensor)'!N28 -> mW | D90: =SUMPRODUCT(D56:D76, $V56:$V76) -> 132.4025 | E90: =SUMPRODUCT(E56:E76, $V56:$V76) -> 131.8745 | F90: =SUMPRODUCT(F56:F76, $V56:$V76) -> 134.18305 | G90: =SUMPRODUCT(G56:G76, $V56:$V76) -> 133.3595 | H90: =SUMPRODUCT(H56:H76, $V56:$V76) -> 130.4345 | I90: =SUMPRODUCT(I56:I76, $V56:$V76) -> 129.4345 | J90: =SUMPRODUCT(J56:J76, $V56:$V76) -> 134.1845 | K90: =SUMPRODUCT(K56:K76, $V56:$V76) -> 134.1845 | ... O90: =SUMPRODUCT(O56:O76, $V56:$V76) -> 134.1845 | R90: ='System Parameters (Sensor)'!Q29 -> 0 | S90: ='System Parameters (Sensor)'!I42 -> 0 | T90: ='System Parameters (Sensor)'!J42 -> 0 | U90: ='System Parameters (Sensor)'!K42 -> 0 | V90: ='System Parameters (Sensor)'!L42 -> 0
...

Sheet System Parameters Device
A3: System Parameters (defined by hardware) | E3: Profiles (usage of each component mode - defined by software and usage)
B4: form the datasheets
E5: "off" | F5: "sensing" | G5: "interactive"
A6: Processor
A7: Active | B7: 89.1 | C7: mW | E7: 0 | F7: 0.07 | G7: 0
A8: Idle | B8: 33 | C8: mW | E8: 0 | F8: 0.93 | G8: 0
A9: Sleep | B9: 0.145 | C9: mW | E9: 1 | F9: 0 | G9: 0
A11: LED
A12: On | B12: 0 | C12: mW | E12: 0 | F12: 0 | G12: 0
A15: Sensor
A16: On | B16: 0.036 | C16: mW | E16: 0 | F16: 1 | G16: 0
A17: Idle | B17: 0.02 | C17: mW | E17: 0 | F17: 0 | G17: 0
A18: Off | B18: 0 | C18: mW | E18: 1 | F18: 0 | G18: 0
A20: Display
A21: On | B21: 0 | C21: mW | E21: 0 | F21: 0 | G21: 0
A22: Off (leakage) | B22: 0 | C22: mW | E22: 0 | F22: 0 | G22: 0
A24: Radio
A25: Data Rate | B25: 0 | C25: bps | E25: 0 | F25: 0 | G25: 0 | L25: Total power in profile (mw) | O25: Maximum Time
A26: Standby Power | B26: 0 | C26: mW | E26: 0 | F26: 0 | G26: 0 | L26: =E5 -> "off" | M26: =SUMPRODUCT(B7:B28, E7:E28) -> 0.145 | N26: mW | O26: =$M$31/M26 -> 24241.379 | P26: hours
A27: TX Power | B27: 0 | C27: mW | E27: 0 | F27: 0 | G27: 0 | L27: =F5 -> "sensing" | M27: =SUMPRODUCT(B7:B28, F7:F28) -> 36.963 | N27: mW | O27: =$M$31/M27 -> 95.095095 | P27: hours
A28: RX Power | B28: 0 | C28: mW | E28: 0 | F28: 0 | G28: 0 | L28: =G5 -> "interactive" | M28: =SUMPRODUCT(B7:B28, G7:G28) -> 0 | N28: mW | O28: =$M$31/M28 -> #DIV/0! | P28: hours
E30: 16 | F30: 8 | G30: 0 | H30: hours/day typical usage | L30: Effective Battery Capacity
A31: Battery | M31: =B32*B33*B34 -> 3515 | N31: mW*h
A32: Capacity | B32: 1000 | C32: mAh
A33: Nominal Voltage | B33: 3.7 | C33: V | L33: Days of Use | M33: =M31/(E30*M26+F30*M27+G30*M28) -> 11.794352 | N33: days
A34: Regulator Efficiency | B34: 0.95 | L34: Hours of Use | M34: =M33*24 -> 283.06445 | N34: hours
A38: REFLECTIONS : WHAT DID YOU LEARN FROM ANALYZING YOUR POWER. TALK ABOUT SOME POTENTIAL TRADEOFFS.

Sheet Sensitivity Analysis (Device
A50: Linked Data from First Page DO NOT EDIT
A52: ='System Parameters Device'!A3 -> System Parameters (defined by hardware) | B52: ='System Parameters Device'!B3 -> 0 | C52: ='System Parameters Device'!C3 -> 0 | D52: ='System Parameters Device'!D3 -> 0 | T52: ='System Parameters Device'!E3 -> Profiles (usage of each component mode - defined by software and usage) | U52: ='System Parameters Device'!F3 -> 0 | V52: ='System Parameters Device'!G3 -> 0 | W52: ='System Parameters Device'!H3 -> 0
A53: ='System Parameters Device'!A4 -> 0 | B53: ='System Parameters Device'!B4 -> form the datasheets | C53: ='System Parameters Device'!C4 -> 0 | D53: ='System Parameters Device'!D4 -> 0 | T53: ='System Parameters Device'!E4 -> 0 | U53: ='System Parameters Device'!F4 -> 0 | V53: ='System Parameters Device'!G4 -> 0 | W53: ='System Parameters Device'!H4 -> 0
A54: ='System Parameters Device'!A5 -> 0 | B54: ='System Parameters Device'!B5 -> 0 | C54: ='System Parameters Device'!C5 -> 0 | D54: ='System Parameters Device'!D5 -> 0 | T54: ='System Parameters Device'!E5 -> "off" | U54: ='System Parameters Device'!F5 -> "sensing" | V54: ='System Parameters Device'!G5 -> "interactive" | W54: ='System Parameters Device'!H5 -> 0
A55: ='System Parameters Device'!A6 -> Processor | B55: ='System Parameters Device'!B6 -> 0 | C55: ='System Parameters Device'!C6 -> 0 | D55: ='System Parameters Device'!D6 -> 0 | T55: ='System Parameters Device'!E6 -> 0 | U55: ='System Parameters Device'!F6 -> 0 | V55: ='System Parameters Device'!G6 -> 0 | W55: ='System Parameters Device'!H6 -> 0
A56: ='System Parameters Device'!A7 -> Active | B56: ='System Parameters Device'!B7 -> 89.1 | C56: ='System Parameters Device'!C7 -> mW | D56: =$B56*0.9 -> 80.19 | E56: =$B56 -> 89.1 | F56: =$B56 -> 89.1 | G56: =$B56 -> 89.1 | H56: =$B56 -> 89.1 | I56: =$B56 -> 89.1 | J56: =$B56 -> 89.1 | K56: =$B56 -> 89.1 | L56: =$B56 -> 89.1 | ... O56: =$B56 -> 89.1 | T56: ='System Parameters Device'!E7 -> 0 | U56: ='System Parameters Device'!F7 -> 0.07 | V56: ='System Parameters Device'!G7 -> 0 | W56: ='System Parameters Device'!H7 -> 0
A57: ='System Parameters Device'!A8 -> Idle | B57: ='System Parameters Device'!B8 -> 33 | C57: ='System Parameters Device'!C8 -> mW | D57: =$B57 -> 33 | E57: =$B57*0.9 -> 29.7 | F57: =$B57 -> 33 | G57: =$B57 -> 33 | H57: =$B57 -> 33 | I57: =$B57 -> 33 | J57: =$B57 -> 33 | K57: =$B57 -> 33 | L57: =$B57 -> 33 | M57: =$B57 -> 33 | ... O57: =$B57 -> 33 | T57: ='System Parameters Device'!E8 -> 0 | U57: ='System Parameters Device'!F8 -> 0.93 | V57: ='System Parameters Device'!G8 -> 0 | W57: ='System Parameters Device'!H8 -> 0
A58: ='System Parameters Device'!A9 -> Sleep | B58: ='System Parameters Device'!B9 -> 0.145 | C58: ='System Parameters Device'!C9 -> mW | D58: =$B58 -> 0.145 | E58: =$B58 -> 0.145 | F58: =$B58*0.9 -> 0.1305 | G58: =$B58 -> 0.145 | H58: =$B58 -> 0.145 | I58: =$B58 -> 0.145 | J58: =$B58 -> 0.145 | K58: =$B58 -> 0.145 | L58: =$B58 -> 0.145 | M58: =$B58 -> 0.145 | N58: =$B58 -> 0.145 | O58: =$B58 -> 0.145 | T58: ='System Parameters Device'!E9 -> 1 | U58: ='System Parameters Device'!F9 -> 0 | V58: ='System Parameters Device'!G9 -> 0 | W58: ='System Parameters Device'!H9 -> 0
A59: ='System Parameters Device'!A10 -> 0 | B59: ='System Parameters Device'!B10 -> 0 | C59: ='System Parameters Device'!C10 -> 0 | D59: =$B59 -> 0 | E59: =$B59 -> 0 | F59: =$B59 -> 0 | G59: =$B59 -> 0 | H59: =$B59 -> 0 | I59: =$B59 -> 0 | J59: =$B59 -> 0 | K59: =$B59 -> 0 | ... O59: =$B59 -> 0 | T59: ='System Parameters Device'!E10 -> 0 | U59: ='System Parameters Device'!F10 -> 0 | V59: ='System Parameters Device'!G10 -> 0 | W59: ='System Parameters Device'!H10 -> 0
A60: ='System Parameters Device'!A11 -> LED | B60: ='System Parameters Device'!B11 -> 0 | C60: ='System Parameters Device'!C11 -> 0 | D60: =$B60 -> 0 | E60: =$B60 -> 0 | F60: =$B60 -> 0 | G60: =$B60 -> 0 | H60: =$B60 -> 0 | I60: =$B60 -> 0 | J60: =$B60 -> 0 | K60: =$B60 -> 0 | ... O60: =$B60 -> 0 | T60: ='System Parameters Device'!E11 -> 0 | U60: ='System Parameters Device'!F11 -> 0 | V60: ='System Parameters Device'!G11 -> 0 | W60: ='System Parameters Device'!H11 -> 0
A61: ='System Parameters Device'!A12 -> On | B61: ='System Parameters Device'!B12 -> 0 | C61: ='System Parameters Device'!C12 -> mW | D61: =$B61 -> 0 | E61: =$B61 -> 0 | F61: =$B61 -> 0 | G61: =$B61*0.9 -> 0 | H61: =$B61 -> 0 | I61: =$B61 -> 0 | J61: =$B61 -> 0 | K61: =$B61 -> 0 | L61: =$B61 -> 0 | M61: =$B61 -> 0 | N61: =$B61 -> 0 | O61: =$B61 -> 0 | T61: ='System Parameters Device'!E12 -> 0 | U61: ='System Parameters Device'!F12 -> 0 | V61: ='System Parameters Device'!G12 -> 0 | W61: ='System Parameters Device'!H12 -> 0
A62: ='System Parameters Device'!A13 -> 0 | B62: ='System Parameters Device'!B13 -> 0 | C62: ='System Parameters Device'!C13 -> 0 | D62: =$B62 -> 0 | E62: =$B62 -> 0 | F62: =$B62 -> 0 | G62: =$B62 -> 0 | H62: =$B62 -> 0 | I62: =$B62 -> 0 | J62: =$B62 -> 0 | K62: =$B62 -> 0 | ... O62: =$B62 -> 0 | T62: ='System Parameters Device'!E13 -> 0 | U62: ='System Parameters Device'!F13 -> 0 | V62: ='System Parameters Device'!G13 -> 0 | W62: ='System Parameters Device'!H13 -> 0
A63: ='System Parameters Device'!A14 -> 0 | B63: ='System Parameters Device'!B14 -> 0 | C63: ='System Parameters Device'!C14 -> 0 | D63: =$B63 -> 0 | E63: =$B63 -> 0 | F63: =$B63 -> 0 | G63: =$B63 -> 0 | H63: =$B63 -> 0 | I63: =$B63 -> 0 | J63: =$B63 -> 0 | K63: =$B63 -> 0 | ... O63: =$B63 -> 0 | T63: ='System Parameters Device'!E14 -> 0 | U63: ='System Parameters Device'!F14 -> 0 | V63: ='System Parameters Device'!G14 -> 0 | W63: ='System Parameters Device'!H14 -> 0
A64: ='System Parameters Device'!A15 -> Sensor | B64: ='System Parameters Device'!B15 -> 0 | C64: ='System Parameters Device'!C15 -> 0 | D64: =$B64 -> 0 | E64: =$B64 -> 0 | F64: =$B64 -> 0 | G64: =$B64 -> 0 | H64: =$B64 -> 0 | I64: =$B64 -> 0 | J64: =$B64 -> 0 | K64: =$B64 -> 0 | ... O64: =$B64 -> 0 | T64: ='System Parameters Device'!E15 -> 0 | U64: ='System Parameters Device'!F15 -> 0 | V64: ='System Parameters Device'!G15 -> 0 | W64: ='System Parameters Device'!H15 -> 0
A65: ='System Parameters Device'!A16 -> On | B65: ='System Parameters Device'!B16 -> 0.036 | C65: ='System Parameters Device'!C16 -> mW | D65: =$B65 -> 0.036 | E65: =$B65 -> 0.036 | F65: =$B65 -> 0.036 | G65: =$B65 -> 0.036 | H65: =$B65*0.9 -> 0.0324 | I65: =$B65 -> 0.036 | J65: =$B65 -> 0.036 | K65: =$B65 -> 0.036 | L65: =$B65 -> 0.036 | M65: =$B65 -> 0.036 | N65: =$B65 -> 0.036 | O65: =$B65 -> 0.036 | T65: ='System Parameters Device'!E16 -> 0 | U65: ='System Parameters Device'!F16 -> 1 | V65: ='System Parameters Device'!G16 -> 0 | W65: ='System Parameters Device'!H16 -> 0
A66: ='System Parameters Device'!A17 -> Idle | B66: ='System Parameters Device'!B17 -> 0.02 | C66: ='System Parameters Device'!C17 -> mW | D66: =$B66 -> 0.02 | E66: =$B66 -> 0.02 | F66: =$B66 -> 0.02 | G66: =$B66 -> 0.02 | H66: =$B66 -> 0.02 | I66: =$B66*0.9 -> 0.018 | J66: =$B66 -> 0.02 | K66: =$B66 -> 0.02 | L66: =$B66 -> 0.02 | M66: =$B66 -> 0.02 | N66: =$B66 -> 0.02 | O66: =$B66 -> 0.02 | T66: ='System Parameters Device'!E17 -> 0 | U66: ='System Parameters Device'!F17 -> 0 | V66: ='System Parameters Device'!G17 -> 0 | W66: ='System Parameters Device'!H17 -> 0
A67: ='System Parameters Device'!A18 -> Off | B67: ='System Parameters Device'!B18 -> 0 | C67: ='System Parameters Device'!C18 -> mW | D67: =$B67 -> 0 | E67: =$B67 -> 0 | F67: =$B67 -> 0 | G67: =$B67 -> 0 | H67: =$B67 -> 0 | I67: =$B67 -> 0 | J67: =$B67*0.9 -> 0 | K67: =$B67 -> 0 | L67: =$B67 -> 0 | M67: =$B67 -> 0 | N67: =$B67 -> 0 | O67: =$B67 -> 0 | T67: ='System Parameters Device'!E18 -> 1 | U67: ='System Parameters Device'!F18 -> 0 | V67: ='System Parameters Device'!G18 -> 0 | W67: ='System Parameters Device'!H18 -> 0
A68: ='System Parameters Device'!A19 -> 0 | B68: ='System Parameters Device'!B19 -> 0 | C68: ='System Parameters Device'!C19 -> 0 | D68: =$B68 -> 0 | E68: =$B68 -> 0 | F68: =$B68 -> 0 | G68: =$B68 -> 0 | H68: =$B68 -> 0 | I68: =$B68 -> 0 | J68: =$B68 -> 0 | K68: =$B68 -> 0 | ... O68: =$B68 -> 0 | T68: ='System Parameters Device'!E19 -> 0 | U68: ='System Parameters Device'!F19 -> 0 | V68: ='System Parameters Device'!G19 -> 0 | W68: ='System Parameters Device'!H19 -> 0
A69: ='System Parameters Device'!A20 -> Display | B69: ='System Parameters Device'!B20 -> 0 | C69: ='System Parameters Device'!C20 -> 0 | D69: =$B69 -> 0 | E69: =$B69 -> 0 | F69: =$B69 -> 0 | G69: =$B69 -> 0 | H69: =$B69 -> 0 | I69: =$B69 -> 0 | J69: =$B69 -> 0 | K69: =$B69 -> 0 | ... O69: =$B69 -> 0 | T69: ='System Parameters Device'!E20 -> 0 | U69: ='System Parameters Device'!F20 -> 0 | V69: ='System Parameters Device'!G20 -> 0 | W69: ='System Parameters Device'!H20 -> 0
A70: ='System Parameters Device'!A21 -> On | B70: ='System Parameters Device'!B21 -> 0 | C70: ='System Parameters Device'!C21 -> mW | D70: =$B70 -> 0 | E70: =$B70 -> 0 | F70: =$B70 -> 0 | G70: =$B70 -> 0 | H70: =$B70 -> 0 | I70: =$B70 -> 0 | J70: =$B70 -> 0 | K70: =$B70*0.9 -> 0 | L70: =$B70 -> 0 | M70: =$B70 -> 0 | N70: =$B70 -> 0 | O70: =$B70 -> 0 | T70: ='System Parameters Device'!E21 -> 0 | U70: ='System Parameters Device'!F21 -> 0 | V70: ='System Parameters Device'!G21 -> 0 | W70: ='System Parameters Device'!H21 -> 0
A71: ='System Parameters Device'!A22 -> Off (leakage) | B71: ='System Parameters Device'!B22 -> 0 | C71: ='System Parameters Device'!C22 -> mW | D71: =$B71 -> 0 | E71: =$B71 -> 0 | F71: =$B71 -> 0 | G71: =$B71 -> 0 | H71: =$B71 -> 0 | I71: =$B71 -> 0 | J71: =$B71 -> 0 | K71: =$B71 -> 0 | L71: =$B71*0.9 -> 0 | M71: =$B71 -> 0 | N71: =$B71 -> 0 | O71: =$B71 -> 0 | T71: ='System Parameters Device'!E22 -> 0 | U71: ='System Parameters Device'!F22 -> 0 | V71: ='System Parameters Device'!G22 -> 0 | W71: ='System Parameters Device'!H22 -> 0
A72: ='System Parameters Device'!A23 -> 0 | B72: ='System Parameters Device'!B23 -> 0 | C72: ='System Parameters Device'!C23 -> 0 | D72: =$B72 -> 0 | E72: =$B72 -> 0 | F72: =$B72 -> 0 | G72: =$B72 -> 0 | H72: =$B72 -> 0 | I72: =$B72 -> 0 | J72: =$B72 -> 0 | K72: =$B72 -> 0 | ... O72: =$B72 -> 0 | T72: ='System Parameters Device'!E23 -> 0 | U72: ='System Parameters Device'!F23 -> 0 | V72: ='System Parameters Device'!G23 -> 0 | W72: ='System Parameters Device'!H23 -> 0
A73: ='System Parameters Device'!A24 -> Radio | B73: ='System Parameters Device'!B24 -> 0 | C73: ='System Parameters Device'!C24 -> 0 | D73: =$B73 -> 0 | E73: =$B73 -> 0 | F73: =$B73 -> 0 | G73: =$B73 -> 0 | H73: =$B73 -> 0 | I73: =$B73 -> 0 | J73: =$B73 -> 0 | K73: =$B73 -> 0 | ... O73: =$B73 -> 0 | T73: ='System Parameters Device'!E24 -> 0 | U73: ='System Parameters Device'!F24 -> 0 | V73: ='System Parameters Device'!G24 -> 0 | W73: ='System Parameters Device'!H24 -> 0
A74: ='System Parameters Device'!A26 -> Standby Power | B74: ='System Parameters Device'!B26 -> 0 | C74: ='System Parameters Device'!C26 -> mW | D74: =$B74 -> 0 | E74: =$B74 -> 0 | F74: =$B74 -> 0 | G74: =$B74 -> 0 | H74: =$B74 -> 0 | I74: =$B74 -> 0 | J74: =$B74 -> 0 | K74: =$B74 -> 0 | L74: =$B74 -> 0 | M74: =$B74*0.9 -> 0 | N74: =$B74 -> 0 | O74: =$B74 -> 0 | T74: ='System Parameters Device'!E26 -> 0 | U74: ='System Parameters Device'!F26 -> 0 | V74: ='System Parameters Device'!G26 -> 0 | W74: ='System Parameters Device'!H26 -> 0
A75: ='System Parameters Device'!A27 -> TX Power | B75: ='System Parameters Device'!B27 -> 0 | C75: ='System Parameters Device'!C27 -> mW | D75: =$B75 -> 0 | E75: =$B75 -> 0 | F75: =$B75 -> 0 | G75: =$B75 -> 0 | H75: =$B75 -> 0 | I75: =$B75 -> 0 | J75: =$B75 -> 0 | K75: =$B75 -> 0 | ... M75: =$B75 -> 0 | N75: =$B75*0.9 -> 0 | O75: =$B75 -> 0 | T75: ='System Parameters Device'!E27 -> 0 | U75: ='System Parameters Device'!F27 -> 0 | V75: ='System Parameters Device'!G27 -> 0 | W75: ='System Parameters Device'!H27 -> 0
A76: ='System Parameters Device'!A28 -> RX Power | B76: ='System Parameters Device'!B28 -> 0 | C76: ='System Parameters Device'!C28 -> mW | D76: =$B76 -> 0 | E76: =$B76 -> 0 | F76: =$B76 -> 0 | G76: =$B76 -> 0 | H76: =$B76 -> 0 | I76: =$B76 -> 0 | J76: =$B76 -> 0 | K76: =$B76 -> 0 | ... N76: =$B76 -> 0 | O76: =$B76*0.9 -> 0 | T76: ='System Parameters Device'!E28 -> 0 | U76: ='System Parameters Device'!F28 -> 0 | V76: ='System Parameters Device'!G28 -> 0 | W76: ='System Parameters Device'!H28 -> 0
A77: ='System Parameters Device'!A29 -> 0 | B77: ='System Parameters Device'!B29 -> 0 | C77: ='System Parameters Device'!C29 -> 0 | D77: ='System Parameters Device'!D29 -> 0 | T77: ='System Parameters Device'!E29 -> 0 | U77: ='System Parameters Device'!F29 -> 0 | V77: ='System Parameters Device'!G29 -> 0 | W77: ='System Parameters Device'!H29 -> 0
A78: ='System Parameters Device'!A30 -> 0 | B78: ='System Parameters Device'!B30 -> 0 | C78: ='System Parameters Device'!C30 -> 0 | D78: ='System Parameters Device'!D30 -> 0 | T78: ='System Parameters Device'!E30 -> 16 | U78: ='System Parameters Device'!F30 -> 8 | V78: ='System Parameters Device'!G30 -> 0 | W78: ='System Parameters Device'!H30 -> hours/day typical usage
A79: ='System Parameters Device'!A31 -> Battery | B79: ='System Parameters Device'!B31 -> 0 | C79: ='System Parameters Device'!C31 -> 0 | D79: ='System Parameters Device'!D31 -> 0 | T79: ='System Parameters Device'!E31 -> 0 | U79: ='System Parameters Device'!F31 -> 0 | V79: ='System Parameters Device'!G31 -> 0 | W79: ='System Parameters Device'!H31 -> 0
A80: ='System Parameters Device'!A32 -> Capacity | B80: ='System Parameters Device'!B32 -> 1000 | C80: ='System Parameters Device'!C32 -> mAh | D80: ='System Parameters Device'!D32 -> 0 | T80: ='System Parameters Device'!E32 -> 0 | U80: ='System Parameters Device'!F32 -> 0 | V80: ='System Parameters Device'!G32 -> 0 | W80: ='System Parameters Device'!H32 -> 0
A81: ='System Parameters Device'!A33 -> Nominal Voltage | B81: ='System Parameters Device'!B33 -> 3.7 | C81: ='System Parameters Device'!C33 -> V | D81: ='System Parameters Device'!D33 -> 0 | T81: ='System Parameters Device'!E33 -> 0 | U81: ='System Parameters Device'!F33 -> 0 | V81: ='System Parameters Device'!G33 -> 0 | W81: ='System Parameters Device'!H33 -> 0
A82: ='System Parameters Device'!A34 -> Regulator Efficiency | B82: ='System Parameters Device'!B34 -> 0.95 | C82: ='System Parameters Device'!C34 -> 0 | D82: ='System Parameters Device'!D34 -> 0 | T82: ='System Parameters Device'!E34 -> 0 | U82: ='System Parameters Device'!F34 -> 0 | V82: ='System Parameters Device'!G34 -> 0 | W82: ='System Parameters Device'!H34 -> 0
A83: ='System Parameters Device'!A35 -> 0 | B83: ='System Parameters Device'!B35 -> 0 | C83: ='System Parameters Device'!C35 -> 0 | D83: ='System Parameters Device'!D35 -> 0 | O83: ='System Parameters Device'!E35 -> 0 | P83: ='System Parameters Device'!F35 -> 0 | Q83: ='System Parameters Device'!G35 -> 0 | R83: ='System Parameters Device'!H35 -> 0 | S83: ='System Parameters Device'!I35 -> 0 | T83: ='System Parameters Device'!J35 -> 0 | U83: =#REF! -> #REF! | V83: =#REF! -> #REF!
A84: ='System Parameters Device'!A36 -> 0 | B84: ='System Parameters Device'!B36 -> 0 | C84: ='System Parameters Device'!C36 -> 0 | D84: ='System Parameters Device'!D36 -> 0 | O84: ='System Parameters Device'!E36 -> 0 | P84: ='System Parameters Device'!F36 -> 0 | Q84: ='System Parameters Device'!G36 -> 0 | R84: ='System Parameters Device'!H36 -> 0 | S84: ='System Parameters Device'!I36 -> 0 | T84: ='System Parameters Device'!J36 -> 0 | U84: =#REF! -> #REF! | V84: =#REF! -> #REF!
A85: ='System Parameters Device'!A37 -> 0 | B85: ='System Parameters Device'!K24 -> 0 | C85: ='System Parameters Device'!L24 -> 0 | D85: ='System Parameters Device'!M24 -> 0 | O85: ='System Parameters Device'!N24 -> 0 | P85: ='System Parameters Device'!O24 -> 0 | Q85: ='System Parameters Device'!P24 -> 0 | R85: ='System Parameters Device'!Q24 -> 0 | S85: ='System Parameters Device'!I37 -> 0 | T85: ='System Parameters Device'!J37 -> 0 | U85: =#REF! -> #REF! | V85: =#REF! -> #REF!
A86: ='System Parameters Device'!A38 -> REFLECTIONS : WHAT DID YOU LEARN FROM ANALYZING YOUR POWER. TALK ABOUT SOME POTENTIAL TRADEOFFS. | B86: ='System Parameters Device'!K25 -> 0 | C86: =#REF! -> #REF! | D86: =#REF! -> #REF! | O86: =#REF! -> #REF! | P86: =#REF! -> #REF! | Q86: =#REF! -> #REF! | R86: ='System Parameters Device'!Q25 -> 0 | S86: ='System Parameters Device'!I38 -> 0 | T86: ='System Parameters Device'!J38 -> 0 | U86: =#REF! -> #REF! | V86: =#REF! -> #REF!
A87: ='System Parameters Device'!L25 -> Total power in profile (mw) | B87: ='System Parameters Device'!M25 -> 0 | C87: ='System Parameters Device'!N25 -> 0 | R87: ='System Parameters Device'!Q26 -> 0 | S87: ='System Parameters Device'!I39 -> 0 | T87: ='System Parameters Device'!J39 -> 0 | U87: ='System Parameters Device'!K39 -> 0 | V87: ='System Parameters Device'!L39 -> 0
A88: ='System Parameters Device'!L26 -> "off" | B88: =SUMPRODUCT(B56:B76, $T56:$T76) -> 0.145 | C88: ='System Parameters Device'!N26 -> mW | D88: =SUMPRODUCT(D56:D76, $T56:$T76) -> 0.145 | E88: =SUMPRODUCT(E56:E76, $T56:$T76) -> 0.145 | F88: =SUMPRODUCT(F56:F76, $T56:$T76) -> 0.1305 | G88: =SUMPRODUCT(G56:G76, $T56:$T76) -> 0.145 | H88: =SUMPRODUCT(H56:H76, $T56:$T76) -> 0.145 | I88: =SUMPRODUCT(I56:I76, $T56:$T76) -> 0.145 | J88: =SUMPRODUCT(J56:J76, $T56:$T76) -> 0.145 | K88: =SUMPRODUCT(K56:K76, $T56:$T76) -> 0.145 | ... O88: =SUMPRODUCT(O56:O76, $T56:$T76) -> 0.145 | R88: ='System Parameters Device'!Q27 -> 0 | S88: ='System Parameters Device'!I40 -> 0 | T88: ='System Parameters Device'!J40 -> 0 | U88: ='System Parameters Device'!K40 -> 0 | V88: ='System Parameters Device'!L40 -> 0
A89: ='System Parameters Device'!L27 -> "sensing" | B89: =SUMPRODUCT(B56:B76,$U56:$U76) -> 36.963 | C89: ='System Parameters Device'!N27 -> mW | D89: =SUMPRODUCT(D56:D76,$U56:$U76) -> 36.3393 | E89: =SUMPRODUCT(E56:E76,$U56:$U76) -> 33.894 | F89: =SUMPRODUCT(F56:F76,$U56:$U76) -> 36.963 | G89: =SUMPRODUCT(G56:G76,$U56:$U76) -> 36.963 | H89: =SUMPRODUCT(H56:H76,$U56:$U76) -> 36.9594 | I89: =SUMPRODUCT(I56:I76,$U56:$U76) -> 36.963 | J89: =SUMPRODUCT(J56:J76,$U56:$U76) -> 36.963 | K89: =SUMPRODUCT(K56:K76,$U56:$U76) -> 36.963 | ... O89: =SUMPRODUCT(O56:O76,$U56:$U76) -> 36.963 | R89: ='System Parameters Device'!Q28 -> 0 | S89: ='System Parameters Device'!I41 -> 0 | T89: ='System Parameters Device'!J41 -> 0 | U89: ='System Parameters Device'!K41 -> 0 | V89: ='System Parameters Device'!L41 -> 0
A90: ='System Parameters Device'!L28 -> "interactive" | B90: =SUMPRODUCT(B56:B76, $V56:$V76) -> 0 | C90: ='System Parameters Device'!N28 -> mW | D90: =SUMPRODUCT(D56:D76, $V56:$V76) -> 0 | E90: =SUMPRODUCT(E56:E76, $V56:$V76) -> 0 | F90: =SUMPRODUCT(F56:F76, $V56:$V76) -> 0 | G90: =SUMPRODUCT(G56:G76, $V56:$V76) -> 0 | H90: =SUMPRODUCT(H56:H76, $V56:$V76) -> 0 | I90: =SUMPRODUCT(I56:I76, $V56:$V76) -> 0 | J90: =SUMPRODUCT(J56:J76, $V56:$V76) -> 0 | K90: =SUMPRODUCT(K56:K76, $V56:$V76) -> 0 | ... O90: =SUMPRODUCT(O56:O76, $V56:$V76) -> 0 | R90: ='System Parameters Device'!Q29 -> 0 | S90: ='System Parameters Device'!I42 -> 0 | T90: ='System Parameters Device'!J42 -> 0 | U90: ='System Parameters Device'!K42 -> 0 | V90: ='System Parameters Device'!L42 -> 0
...
